<?xml version="1.0"?>
<robot name="smartcar" xmlns:xacro="http://www.ros.org/wiki/xacro">
	<link name="base_link">
		<visual>
			<geometry>
				<cylinder length="0.02" radius="0.25" />
			</geometry>
			<origin rpy="0 0 0" xyz="0 0 0" />
			<material name="blue">
				<color rgba="0 .5 .8 1" />
			</material>
		</visual>
		<collision>
			<geometry>
				<cylinder length="0.02" radius="0.25" />
			</geometry>
		</collision>
		<inertial>
			<mass value="1.0" />
			<inertia ixx="0.0054" iyy="0.0073" izz="0.0023" ixy="0" ixz="0" iyz="0" />
		</inertial>
	</link>
	<link name="dummy">
	</link>
	<joint name="dummy_joint" type="fixed">
		<parent link="dummy" />
		<child link="base_link" />
	</joint>
	<gazebo reference="base_link">
		<material>
			Gazebo/Blue
		</material>
	</gazebo>

    	<xacro:macro name="cylinder_inertial_matrix" params="m r h">
        	<inertial>
            	<mass value="${m}" />
            	<inertia ixx="${m*(3*r*r+h*h)/12}" ixy = "0" ixz = "0"
                	iyy="${m*(3*r*r+h*h)/12}" iyz = "0"
                	izz="${m*r*r/2}" /> 
        	</inertial>
    	</xacro:macro>
	
	<xacro:macro name="wheel" params="prefix x y z">
		<link name="${prefix}_wheel">
			<visual>
				<geometry>
					<cylinder length=".02" radius="0.025" />
				</geometry>
				<material name="black">
					<color rgba="0 0 0 1" />
				</material>
			</visual>
			<collision>
				<geometry>
					<cylinder length=".02" radius="0.025" />
				</geometry>
			</collision>
			<xacro:cylinder_inertial_matrix m="1.0" r="0.025" h="0.02" />
		</link>

		<joint name="${prefix}_wheel_joint" type="continuous">
			<axis xyz="0 0 1" />
			<parent link="base_link" />
			<child link="${prefix}_wheel" />
			<origin rpy="1.57075 0 0" xyz="${x} ${y} ${z}" />
			<limit effort="100" velocity="100" />
			<joint_properties damping="0.0" friction="0.0" />
		</joint>

		<gazebo reference="${prefix}_wheel">
			<material>
				Gazebo/Black
			</material>
		</gazebo>
	</xacro:macro>

	<xacro:wheel prefix="front" x="0.2" y="0" z="-0.03" />
	<xacro:wheel prefix="right_back" x="-0.1" y="0.1" z="-0.03"/>
	<xacro:wheel prefix="left_back" x="-0.1" y="-0.1" z="-0.03" />

	<gazebo>
		<plugin name="differential_drive_controller" filename="libgazebo_ros_diff_drive.so">
			<rosDebugLevel>
				na
			</rosDebugLevel>
			<commandTopic>
				cmd_vel
			</commandTopic>
			<odometryTopic>
				odom
			</odometryTopic>
			<odometryFrame>
				odom
			</odometryFrame>
			<publishWheelTF>
				false
			</publishWheelTF>
			<publishOdomTF>
				true
			</publishOdomTF>
			<wheelAcceleration>
				0
			</wheelAcceleration>
			<wheelTorque>
				5
			</wheelTorque>
			<updateRate>
				100
			</updateRate>
			<odometrySource>
				1
			</odometrySource>
			<publishTf>
				1
			</publishTf>
			<leftJoint>
				left_back_wheel_joint
			</leftJoint>
			<rightJoint>
				right_back_wheel_joint
			</rightJoint>
			<robotBaseFrame>
				base_link
			</robotBaseFrame>
			<wheelSeparation>
				0.14
			</wheelSeparation>
			<wheelDiameter>
				0.05
			</wheelDiameter>
			<legacyMode>
				true
			</legacyMode>
			<publishWheelJointState>
				true
			</publishWheelJointState>
		</plugin>
	</gazebo>
	<joint name="laser_joint" type="fixed">
		<axis xyz="0 1 0" />
		<origin xyz="0 0 0.030" rpy="0 0 0" />
		<parent link="base_link" />
		<child link="laser_link" />
	</joint>
	<link name="laser_link">
		<collision>
			<origin xyz="0 0 0" rpy="0 0 0" />
			<geometry>
				<box size="0.02 .03 .03" />
			</geometry>
		</collision>
		<visual>
			<origin xyz="0 0 0" rpy="0 0 0" />
			<geometry>
				<box size="0.02 .03 .03" />
			</geometry>
		</visual>
		<inertial>
			<mass value="0.1" />
			<inertia ixx="0.000010833" iyy="0.000010833" izz="0.000015" ixy="0" ixz="0" iyz="0" />
		</inertial>
	</link>
	<gazebo reference="laser_link">
		<material>
			Gazebo/Black
		</material>
	</gazebo>
	<gazebo reference="laser_link">
		<sensor type="ray" name="head_velodyne_sensor">
			<pose>
				0 0 0 0 0 0
			</pose>
			<visualize>
				true
			</visualize>
			<update_rate>
				40
			</update_rate>
			<ray>
				<scan>
					<horizontal>
						<samples>
							40
						</samples>
						<resolution>
							1
						</resolution>
						<min_angle>
							0
						</min_angle>
						<max_angle>
							1.57
						</max_angle>
					</horizontal>
					<vertical>
						<samples>
							40
						</samples>
						<resolution>
							1
						</resolution>
						<min_angle>
							-${15.0*3.14125/180.0}
						</min_angle>
						<max_angle>
							${15.0*3.14125/180.0}
						</max_angle>
					</vertical>
				</scan>
				<range>
					<min>
						0.10
					</min>
					<max>
						60.0
					</max>
					<resolution>
						0.02
					</resolution>
				</range>
			</ray>
			<plugin name="gazebo_ros_head_velodyne_controller" filename="libgazebo_ros_velodyne_laser.so">
				<frameName>
					laser_link
				</frameName>
				<topicName>
					velodyne_pointcloud
				</topicName>
			</plugin>
		</sensor>
	</gazebo>
</robot>
