<?xml version="1.0"?>
<robot name="smartcar">
	<link name="base_link">
		<visual>
			<geometry>
				<box size="0.25 .16 .05" />
			</geometry>
			<origin rpy="0 0 1.57075" xyz="0 0 0" />
			<material name="blue">
				<color rgba="0 .5 .8 1" />
			</material>
		</visual>
		
		<collision>
			
			<geometry>
				
				<box size="0.25 .16 .05" />
				
			</geometry>
			
		</collision>
		
		<inertial>
			
			<mass value="1.0" />
			
			<inertia ixx="0.0054" iyy="0.0073" izz="0.0023" ixy="0" ixz="0" iyz="0" />
			
		</inertial>
	</link>
	<gazebo reference="base_link">
		<material>
			Gazebo/Blue
		</material>
	</gazebo>
	<link name="right_front_wheel">
		<visual>
			<geometry>
				<cylinder length=".02" radius="0.025" />
			</geometry>
			<material name="black">
				<color rgba="0 0 0 1" />
			</material>
		</visual>
		
		<collision>
			
			<geometry>
				
				<cylinder length=".02" radius="0.025" />
				
			</geometry>
			
		</collision>
		
		<inertial>
			
			<mass value="0.1" />
			
			<inertia ixx="0.0000189" iyy=".0000189583" izz="0.00003125" ixy="0" ixz="0" iyz="0" />
			
		</inertial>
	</link>
	<joint name="right_front_wheel_joint" type="continuous">
		<axis xyz="0 0 1" />
		<parent link="base_link" />
		<child link="right_front_wheel" />
		<origin rpy="0 1.57075 0" xyz="0.08 0.1 -0.03" />
		<limit effort="100" velocity="100" />
		<joint_properties damping="0.0" friction="0.0" />
	</joint>
	<gazebo reference="right_front_wheel">
		<material>
			Gazebo/Black
		</material>
	</gazebo>
	<link name="right_back_wheel">
		<visual>
			<geometry>
				<cylinder length=".02" radius="0.025" />
			</geometry>
			<material name="black">
				<color rgba="0 0 0 1" />
			</material>
		</visual>
		
		<collision>
			
			<geometry>
				
				<cylinder length=".02" radius="0.025" />
				
			</geometry>
			
		</collision>
		
		<inertial>
			
			<mass value="0.1" />
			
			<inertia ixx="0.0000189" iyy=".0000189583" izz="0.00003125" ixy="0" ixz="0" iyz="0" />
			
		</inertial>
	</link>
	<joint name="right_back_wheel_joint" type="continuous">
		<axis xyz="0 0 1" />
		<parent link="base_link" />
		<child link="right_back_wheel" />
		<origin rpy="0 1.57075 0" xyz="0.08 -0.1 -0.03" />
		<limit effort="100" velocity="100" />
		<joint_properties damping="0.0" friction="0.0" />
	</joint>
	<gazebo reference="right_back_wheel">
		<material>
			Gazebo/Black
		</material>
	</gazebo>
	<link name="left_front_wheel">
		<visual>
			<geometry>
				<cylinder length=".02" radius="0.025" />
			</geometry>
			<material name="black">
				<color rgba="0 0 0 1" />
			</material>
		</visual>
		
		<collision>
			
			<geometry>
				
				<cylinder length=".02" radius="0.025" />
				
			</geometry>
			
		</collision>
		
		<inertial>
			
			<mass value="0.1" />
			
			<inertia ixx="0.0000189" iyy=".0000189583" izz="0.00003125" ixy="0" ixz="0" iyz="0" />
			
		</inertial>
	</link>
	<joint name="left_front_wheel_joint" type="continuous">
		<axis xyz="0 0 1" />
		<parent link="base_link" />
		<child link="left_front_wheel" />
		<origin rpy="0 1.57075 0" xyz="-0.08 0.1 -0.03" />
		<limit effort="100" velocity="100" />
		<joint_properties damping="0.0" friction="0.0" />
	</joint>
	<gazebo reference="left_front_wheel">
		<material>
			Gazebo/Black
		</material>
	</gazebo>
	<link name="left_back_wheel">
		<visual>
			<geometry>
				<cylinder length=".02" radius="0.025" />
			</geometry>
			<material name="black">
				<color rgba="0 0 0 1" />
			</material>
		</visual>
		
		<collision>
			
			<geometry>
				
				<cylinder length=".02" radius="0.025" />
				
			</geometry>
			
		</collision>
		
		<inertial>
			
			<mass value="0.1" />
			
			<inertia ixx="0.0000189" iyy=".0000189583" izz="0.00003125" ixy="0" ixz="0" iyz="0" />
			
		</inertial>
	</link>
	<joint name="left_back_wheel_joint" type="continuous">
		<axis xyz="0 0 1" />
		<parent link="base_link" />
		<child link="left_back_wheel" />
		<origin rpy="0 1.57075 0" xyz="-0.08 -0.1 -0.03" />
		<limit effort="100" velocity="100" />
		<joint_properties damping="0.0" friction="0.0" />
	</joint>
	<gazebo reference="left_back_wheel">
		<material>
			Gazebo/Black
		</material>
	</gazebo>
	<link name="head">
		<visual>
			<geometry>
				<box size=".02 .03 .03" />
			</geometry>
			<material name="white">
				<color rgba="1 1 1 1" />
			</material>
		</visual>
		
		<collision>
			
			<geometry>
				
				<box size="0.02 .03 .03" />
				
			</geometry>
			
		</collision>
		
		<inertial>
			
			<mass value="0.1" />
			
			<inertia ixx="0.000010833" iyy="0.000010833" izz="0.000015" ixy="0" ixz="0" iyz="0" />
			
		</inertial>
	</link>
	<joint name="tobox" type="fixed">
		<parent link="base_link" />
		<child link="head" />
		<origin xyz="0 -0.08 0.025" rpy="0 0 1.57" />
	</joint>
	<gazebo reference="tobox">
		<material>
			Gazebo/White
		</material>
	</gazebo>
	<gazebo>
		<plugin name="differential_drive_controller" filename="libgazebo_ros_diff_drive.so">
			<leftJoint>
				left_front_wheel_joint
			</leftJoint>
			<rightJoint>
				right_front_wheel_joint
			</rightJoint>
			<robotBaseFrame>
				base_link
			</robotBaseFrame>
			<wheelSeparation>
				0.14
			</wheelSeparation>
			<wheelDiameter>
				0.05
			</wheelDiameter>
			<legacyMode>
				true
			</legacyMode>
			<publishWheelJointState>
				true
			</publishWheelJointState>
		</plugin>
		<plugin name="differential_drive_controller" filename="libgazebo_ros_diff_drive.so">
			<leftJoint>
				left_back_wheel_joint
			</leftJoint>
			<rightJoint>
				right_back_wheel_joint
			</rightJoint>
			<robotBaseFrame>
				base_link
			</robotBaseFrame>
			<wheelSeparation>
				0.14
			</wheelSeparation>
			<wheelDiameter>
				0.05
			</wheelDiameter>
			<legacyMode>
				true
			</legacyMode>
			<publishWheelJointState>
				true
			</publishWheelJointState>
			<publishOdom>
				true
			</publishOdom>
			<robotBaseFrame>
				base_link
			</robotBaseFrame>
		</plugin>
	</gazebo>
</robot>
